Workbook

Sheet גיליון1
A1: מזהה תקופה | B1: שם עובד | C1: מחלקה | D1: תאריך התחלה | E1: תאריך סיום | F1: חודש | G1: סה"כ ימים | H1: ימי א-ה | I1: ימי שישי | J1: ימי שבת | K1: ימי חג | L1: תעריף יומי | M1: תשלום מעסיק (א-ה) | N1: פיצוי 20% למעסיק | O1: תוספת 40% | P1: סה"כ תגמול מביטוח לאומי ₪ | Q1: מועד תשלום ביטוח לאומי | R1: סכום הפרשים לעובד ₪ | S1: חודש ביצוע תשלום | T1: 💰 הערות
A2: P0003 | B2: אייל מלח | C2: רפאל | D2: 01/01/2025 | E2: 03/01/2025 | F2: 01/2025 | G2: 3 | H2: 3 | I2: 0 | J2: 0 | K2: 0 | L2: 801.06 | M2: =L2*H2 -> 2403.18 | P2: =גיליון2!O23 -> 2206 | Q2: 45697 | R2: =P2-M2 -> -197.18 | T2: במרכז
A3: P0008 | B3: אריאל אליה | C3: מל"מ | D3: 19/01/2025 | E3: 22/01/2025 | F3: 01/2025 | G3: 4 | H3: 4 | I3: 0 | J3: 0 | K3: 0 | L3: 876.93 | M3: =L3*H3 -> 3507.72 | P3: =גיליון2!O24 -> 3710 | Q3: 45700 | R3: =P3-M3 -> 202.28 | S3: 45717
A4: P0014 | B4: דניאל בנדרימר | C4: מל"מ | D4: 26/01/2025 | E4: 30/01/2025 | F4: 01/2025 | G4: 5 | H4: 5 | I4: 0 | J4: 1 | K4: 0 | L4: 670.60452 | M4: =L4*H4 -> 3353.0226 | P4: =גיליון2!O26 -> 3981 | Q4: =גיליון2!X26 -> 45700 | R4: =P4-M4 -> 627.97739 | S4: 45717
A5: P0026 | B5: יורם שלמה | C5: רוה"מ | D5: 01/01/2025 | E5: 01/01/2025 | F5: 01/2025 | G5: 1 | H5: 1 | I5: 0 | J5: 0 | K5: 0 | L5: 1096.1698 | M5: =L5*H5 -> 1096.1698 | P5: =גיליון2!O6 -> 1051 | Q5: =גיליון2!X6 -> 45697 | R5: =P5-M5 -> -45.16982 | S5: 45809
A6: P0026 | B6: יורם שלמה | C6: רוה"מ | D6: 01/01/2025 | E6: 01/01/2025 | F6: 01/2025 | G6: 1 | H6: 1 | I6: 0 | J6: 0 | K6: 0 | O6: =גיליון2!S8 -> 422 | Q6: =גיליון2!X8 -> 45775 | R6: =O6 -> 422 | S6: 45809
A7: P0027 | B7: יורם שלמה | C7: רוה"מ | D7: 19/01/2025 | E7: 23/01/2025 | F7: 01/2025 | G7: 5 | H7: 4 | I7: 0 | J7: 1 | K7: 0 | L7: 1096.1698 | M7: =L7*H7 -> 4384.6793 | P7: =גיליון2!O7 -> 5257 | Q7: =גיליון2!X7 -> 45697 | R7: =P7-M7 -> 872.32072 | S7: 45809
A8: P0055 | B8: לוי דור | C8: רפאל | D8: 22/01/2025 | E8: 30/01/2025 | F8: 01/2025 | G8: 9 | H8: 7 | I8: 1 | J8: 1 | K8: 0 | L8: 826.99585 | M8: =L8*H8 -> 5788.9709 | P8: =גיליון2!O25 -> 6992 | Q8: =גיליון2!X25 -> 45700 | R8: =P8-M8 -> 1203.0291 | S8: 45717 | T8: לבדוק תקינות יום+ הפרש ששולם לא כלל שישי- שבת
A9: P0063 | B9: מנפרד מרקוביץ' | C9: רפאל | D9: 07/01/2025 | E9: 07/01/2025 | F9: 01/2025 | G9: 1 | H9: 1 | I9: 0 | J9: 0 | K9: 0 | L9: 868.57407 | M9: =L9*H9 -> 868.57407 | P9: =גיליון2!O2 -> 1437 | Q9: =גיליון2!X2 -> 45697 | R9: =P9-(L9*G9) -> 568.42593 | S9: 45717
A10: P0063 | B10: מנפרד מרקוביץ' | C10: רפאל | D10: 07/01/2025 | E10: 07/01/2025 | F10: 01/2025 | G10: 1 | H10: 1 | I10: 0 | J10: 0 | K10: 0 | O10: 575 | Q10: 45775 | R10: =O10 -> 575 | S10: 45809
A11: P0064 | B11: מנפרד מרקוביץ' | C11: רפאל | D11: 16/01/2025 | E11: 16/01/2025 | F11: 01/2025 | G11: 1 | H11: 1 | I11: 0 | J11: 0 | K11: 0 | L11: 868.57407 | M11: =L11*H11 -> 868.57407 | P11: =גיליון2!O3 -> 1437 | Q11: =גיליון2!X3 -> 45697 | R11: =P11-(L11*G11) -> 568.42593 | S11: 45717
A12: P0064 | B12: מנפרד מרקוביץ' | C12: רפאל | D12: 16/01/2025 | E12: 16/01/2025 | F12: 01/2025 | G12: 1 | H12: 1 | I12: 0 | J12: 0 | K12: 0 | O12: 575 | Q12: 45775 | R12: =O12 -> 575 | S12: 45809
A13: P0074 | B13: משה בורך | C13: רפאל | D13: 09/01/2025 | E13: 09/01/2025 | F13: 01/2025 | G13: 1 | H13: 1 | I13: 0 | J13: 0 | K13: 0 | L13: =(17000+1265+1885)/21.67 -> 929.85695 | M13: =L13*H13 -> 929.85695 | P13: =גיליון2!O11 -> 763 | Q13: =גיליון2!X11 -> 45708 | R13: =P13-(L13*H13) -> -166.85695 | S13: 45717
A14: P0074 | B14: משה בורך | C14: רפאל | D14: 09/01/2025 | E14: 09/01/2025 | F14: 01/2025 | G14: 1 | H14: 1 | I14: 0 | J14: 0 | K14: 0 | L14: =(17000+1265+1885)/21.67 -> 929.85695 | O14: 305 | Q14: 45775 | R14: =O14 -> 305 | S14: 45809
A15: P0075 | B15: משה בורך | C15: רפאל | D15: 29/01/2025 | E15: 30/01/2025 | F15: 01/2025 | G15: 2 | H15: 2 | I15: 0 | J15: 0 | K15: 0 | L15: 929.85695 | M15: =L15*H15 -> 1859.7139 | P15: =גיליון2!O10 -> 2137 | Q15: =גיליון2!X10 -> 45700 | R15: =P15-(L15*H15) -> 277.28611 | S15: 45717
A16: P0095 | B16: נתן פרדר | C16: רוה"מ | D16: 01/01/2025 | E16: 45660 | F16: 01/2025 | G16: 3 | H16: 3 | I16: 0 | J16: 0 | K16: 0 | L16: 914.85925 | M16: =L16*H16 -> 2744.5778 | P16: =גיליון2!O23 -> 2206 | Q16: =גיליון2!X13 -> 45697 | R16: =P16-(L16*H16) -> -538.57776 | T16: במרכז
A17: P0096 | B17: נתן פרדר | C17: רוה"מ | D17: 05/01/2025 | E17: 11/01/2025 | F17: 01/2025 | G17: 7 | H17: 5 | I17: 1 | J17: 1 | K17: 0 | L17: 914.85925 | M17: =L17*H17 -> 4574.2963 | P17: =SUM(גיליון2!O13:O16) -> 7809 | Q17: =גיליון2!X14 -> 45697 | R17: =P17-(L17*H17) -> 3234.7037 | T17: במרכז
A18: P0097 | B18: נתן פרדר | C18: רוה"מ | D18: 14/01/2025 | E18: 17/01/2025 | F18: 01/2025 | G18: 4 | H18: 4 | I18: 0 | J18: 0 | K18: 0 | L18: 914.85925 | M18: =L18*H18 -> 3659.437 | P18: =גיליון2!O17+גיליון2!O18 -> 4462 | Q18: =גיליון2!X15 -> 45697 | R18: =P18-(L18*H18) -> 802.56299 | T18: במרכז
A19: P0097 | B19: נתן פרדר | C19: רוה"מ | D19: 14/01/2025 | E19: 17/01/2025 | F19: 01/2025 | G19: 4 | H19: 4 | I19: 0 | J19: 0 | K19: 0 | O19: 1785 | Q19: 45775 | R19: =O19 -> 1785 | T19: במרכז
A20: P0098 | B20: נתן פרדר | C20: רוה"מ | D20: 20/01/2025 | E20: 20/01/2025 | F20: 01/2025 | G20: 1 | H20: 1 | I20: 0 | J20: 0 | K20: 0 | L20: 914.85925 | M20: =L20*H20 -> 914.85925 | P20: =גיליון2!O19 -> 1116 | Q20: =גיליון2!X19 -> 45697 | R20: =P20-(L20*H20) -> 201.14075 | T20: במרכז
A21: P0098 | B21: נתן פרדר | C21: רוה"מ | D21: 20/01/2025 | E21: 20/01/2025 | F21: 01/2025 | G21: 1 | H21: 1 | I21: 0 | J21: 0 | K21: 0 | O21: 446 | Q21: 45775 | T21: במרכז
A22: P0099 | B22: נתן פרדר | C22: רוה"מ | D22: 24/01/2025 | E22: 26/01/2025 | F22: 01/2025 | G22: 3 | H22: 1 | I22: 1 | J22: 1 | K22: 0 | L22: 914.85925 | M22: =L22*H22 -> 914.85925 | P22: =גיליון2!O20 -> 1116 | Q22: =גיליון2!X21 -> 45775 | R22: =P22-(L22*H22) -> 201.14075 | T22: במרכז
A23: P0023 | B23: יום טוב מוסארי | C23: רוה"מ | D23: 20/02/2025 | E23: 20/02/2025 | F23: 02/2025 | G23: 1 | H23: 1 | I23: 0 | J23: 0 | K23: 0 | L23: 1282.4642 | M23: =L23*H23 -> 1282.4642 | N23: 256.49285
A24: P0024 | B24: יום טוב מוסארי | C24: רוה"מ | D24: 23/02/2025 | E24: 23/02/2025 | F24: 02/2025 | G24: 1 | H24: 0 | I24: 0 | J24: 1 | K24: 0 | L24: 1282.4642 | M24: =L24*H24 -> 0 | N24: 0
A25: P0027 | B25: יורם שלמה | C25: רוה"מ | D25: 19/01/2025 | E25: 23/01/2025 | F25: 01/2025 | G25: 5 | H25: 4 | I25: 0 | J25: 1 | K25: 0 | O25: =גיליון2!S9 -> 2115 | Q25: =גיליון2!X9 -> 45775 | R25: =O25 -> 2115 | S25: 45809
A26: P0028 | B26: יורם שלמה | C26: רוה"מ | D26: 10/02/2025 | E26: 10/02/2025 | F26: 02/2025 | G26: 1 | H26: 1 | I26: 0 | J26: 0 | K26: 0 | L26: 1096.1698 | M26: =L26*H26 -> 1096.1698 | P26: =גיליון2!O30 -> 1174 | Q26: =גיליון2!X30 -> 45770 | R26: =P26-M26 -> 77.83018
A27: P0029 | B27: יורם שלמה | C27: רוה"מ | D27: 18/02/2025 | E27: 19/02/2025 | F27: 02/2025 | G27: 2 | H27: 2 | I27: 0 | J27: 0 | K27: 0 | L27: 1096.1698 | M27: =L27*H27 -> 2192.3396 | P27: =גיליון2!O31 -> 3287 | Q27: =גיליון2!X31 -> 45770 | R27: =P27-M27 -> 1094.6604
A28: P0030 | B28: יורם שלמה | C28: רוה"מ | D28: 26/02/2025 | E28: 26/02/2025 | F28: 02/2025 | G28: 1 | H28: 1 | I28: 0 | J28: 0 | K28: 0 | L28: 1096.1698 | M28: =L28*H28 -> 1096.1698 | P28: =גיליון2!O32 -> 1174 | Q28: =גיליון2!X32 -> 45770 | R28: =P28-M28 -> 77.83018
A29: P0065 | B29: מנפרד מרקוביץ' | C29: רפאל | D29: 24/02/2025 | E29: 28/02/2025 | F29: 02/2025 | G29: 5 | H29: 5 | I29: 0 | J29: 0 | K29: 0 | L29: 868.57407 | M29: =L29*H29 -> 4342.8703 | P29: =גיליון2!O27 -> 7184 | Q29: =גיליון2!X27 -> 45770 | R29: =P29-(L29*G29) -> 2841.1297
A30: P0076 | B30: משה בורך | C30: רפאל | D30: 23/02/2025 | E30: 23/02/2025 | F30: 02/2025 | G30: 1 | H30: 0 | I30: 0 | J30: 1 | K30: 0 | L30: 929.85695 | M30: =L30*H30 -> 0
A31: P0077 | B31: משה בורך | C31: רפאל | D31: 26/02/2025 | E31: 26/02/2025 | F31: 02/2025 | G31: 1 | H31: 1 | I31: 0 | J31: 0 | K31: 0 | L31: 929.85695 | M31: =L31*H31 -> 929.85695
A32: P0100 | B32: נתן פרדר | C32: רוה"מ | D32: 10/02/2025 | E32: 11/02/2025 | F32: 02/2025 | G32: 2 | H32: 2 | I32: 0 | J32: 0 | K32: 0 | L32: 914.85925 | M32: =L32*H32 -> 1829.7185
A33: P0101 | B33: נתן פרדר | C33: רוה"מ | D33: 13/02/2025 | E33: 13/02/2025 | F33: 02/2025 | G33: 1 | H33: 1 | I33: 0 | J33: 0 | K33: 0 | L33: 914.85925 | M33: =L33*H33 -> 914.85925
A34: P0102 | B34: נתן פרדר | C34: רוה"מ | D34: 17/02/2025 | E34: 18/02/2025 | F34: 02/2025 | G34: 2 | H34: 2 | I34: 0 | J34: 0 | K34: 0 | L34: 914.85925 | M34: =L34*H34 -> 1829.7185
A35: P0103 | B35: נתן פרדר | C35: רוה"מ | D35: 24/02/2025 | E35: 25/02/2025 | F35: 02/2025 | G35: 2 | H35: 2 | I35: 0 | J35: 0 | K35: 0 | L35: 914.85925 | M35: =L35*H35 -> 1829.7185
A36: P0001 | B36: אוראל שווקי | C36: רפאל | D36: 19/03/2025 | E36: 19/03/2025 | F36: 03/2025 | G36: 1 | H36: 1 | I36: 0 | J36: 0 | K36: 0 | L36: 863.72866 | M36: =L36*H36 -> 863.72866 | N36: 172.74573
A37: P0009 | B37: אריאל אליה | C37: מל"מ | D37: 02/03/2025 | E37: 05/03/2025 | F37: 03/2025 | G37: 4 | H37: 3 | I37: 0 | J37: 1 | K37: 0 | L37: 868.85095 | M37: =L37*H37 -> 2606.5528 | N37: 521.31057
A38: P0031 | B38: יורם שלמה | C38: רוה"מ | D38: 04/03/2025 | E38: 04/03/2025 | F38: 03/2025 | G38: 1 | H38: 1 | I38: 0 | J38: 0 | K38: 0 | L38: 1096.1698 | M38: =L38*H38 -> 1096.1698 | P38: =גיליון2!O33 -> 1233 | Q38: =גיליון2!X33 -> 45770 | R38: =P38-M38 -> 136.83018
A39: P0032 | B39: יורם שלמה | C39: רוה"מ | D39: 17/03/2025 | E39: 45735 | F39: 03/2025 | G39: 3 | H39: 3 | I39: 0 | J39: 0 | K39: 0 | L39: 1096.1698 | M39: =L39*H39 -> 3288.5095 | P39: =גיליון2!O34+גיליון2!O35 -> 3699 | Q39: =גיליון2!X33 -> 45770 | R39: =P39-M39 -> 410.49054
A40: P0033 | B40: יורם שלמה | C40: רוה"מ | D40: 30/03/2025 | E40: 45747 | F40: 03/2025 | G40: 2 | H40: 2 | I40: 0 | J40: 0 | K40: 0 | L40: 1096.1698 | M40: =L40*H40 -> 2192.3396 | P40: =גיליון2!O36 -> 2466 | Q40: =גיליון2!X36 -> 45770 | R40: =P40-M40 -> 273.66036
...

Sheet גיליון2
A1: זהות | B1: תאריך שרות | C1: תאריך סיום שרות | D1: ימי שרות | E1: סידורי תביעה | F1: סוג תביעה | G1: סוג שרות | H1: סיבת עיכוב | I1: החלטה | J1: שם משפחה | K1: שם פרטי | L1: קוד שגיאה | M1: תאור שגיאה | N1: סיבת דחיה | O1: תגמול | P1: תגמול נדרש | Q1: פיצוי %20 למעסיק | R1: סכום הצמדה | S1: תוספת 40% לעובד | T1: תאריך משכורת | U1: שיוך מחלקתי | V1: מס' תביעת מעסיק | W1: מנה | X1: ת_תשלום | Y1: חודש שכר תשלום הפרשים
A2: 11915519 | B2: 45664 | C2: 45664 | D2: 1 | E2: 1 | F2: מקור | G2: רגיל | I2: אישור | J2: מרקוביץ' | K2: מנפרד | O2: 1437 | P2: 821 | Q2: 164 | R2: 0 | T2: 45658 | V2: 203 | W2: 203 | X2: 45697
A3: 11915519 | B3: 45673 | C3: 45673 | D3: 1 | E3: 1 | F3: מקור | G3: רגיל | I3: אישור | J3: מרקוביץ' | K3: מנפרד | O3: 1437 | P3: 821 | Q3: 164 | R3: 0 | T3: 45658 | V3: 203 | W3: 203 | X3: 45697
A4: 11915519 | B4: 07/01/2025 | C4: 07/01/2025 | D4: 1 | E4: 1 | I4: תוספת | J4: מרקוביץ' | K4: מנפרד | S4: 578 | T4: 45658 | V4: 203 | W4: 410 | X4: 45775
A5: 11915519 | B5: 16/01/2025 | C5: 16/01/2025 | D5: 1 | E5: 1 | I5: תוספת | J5: מרקוביץ' | K5: מנפרד | S5: 578 | T5: 45658 | V5: 203 | W5: 410 | X5: 45775
A6: 22201347 | B6: 45658 | C6: 45658 | D6: 1 | E6: 1 | F6: מקור | G6: רגיל | I6: אישור | J6: שלמה | K6: יורם | O6: 1051 | P6: 1051 | Q6: 210 | R6: 0 | T6: 45658 | V6: 203 | W6: 203 | X6: 45697
A7: 22201347 | B7: 45676 | C7: 45680 | D7: 5 | E7: 1 | F7: מקור | G7: רגיל | I7: אישור | J7: שלמה | K7: יורם | O7: 5257 | P7: 5257 | Q7: 1051 | R7: 0 | T7: 45658 | V7: 203 | W7: 203 | X7: 45697
A8: 22201347 | B8: 01/01/2025 | C8: 01/01/2025 | D8: 1 | E8: 1 | I8: תוספת | J8: שלמה | K8: יורם | S8: 422 | T8: 45658 | V8: 203 | W8: 410 | X8: 45775
A9: 22201347 | B9: 19/01/2025 | C9: 23/01/2025 | D9: 5 | E9: 5 | I9: תוספת | J9: שלמה | K9: יורם | S9: 2115 | T9: 45658 | V9: 203 | W9: 410 | X9: 45775
A10: 25147505 | B10: 45686 | C10: 45687 | D10: 2 | E10: 1 | F10: מקור | G10: רגיל | I10: אישור | J10: בורך | K10: משה | O10: 2137 | P10: 1506 | Q10: 301 | R10: 0 | T10: 45658 | V10: 203 | W10: 204 | X10: 45700
A11: 25147505 | B11: 45666 | C11: 45666 | D11: 1 | E11: 1 | F11: מקור | G11: רגיל | I11: אישור | J11: בורך | K11: משה | O11: 763 | P11: 753 | Q11: 151 | R11: 0 | T11: 45658 | V11: 203 | W11: 209 | X11: 45708
A12: 25147505 | B12: 09/01/2025 | C12: 09/01/2025 | D12: 1 | E12: 1 | I12: תוספת | J12: בורך | K12: משה | S12: 307 | T12: 45658 | V12: 203 | W12: 410 | X12: 45775
A13: 25155235 | B13: 45667 | C13: 45668 | D13: 2 | E13: 1 | F13: מקור | G13: רגיל | I13: אישור | J13: פרדר | K13: נתן | L13: 6888 | M13: תאריך שרות שונה בהתא | O13: 2231 | P13: 4463 | Q13: 446 | R13: 0 | T13: 45658 | V13: 203 | W13: 203 | X13: 45697
A14: 25155235 | B14: 45662 | C14: 45662 | D14: 1 | E14: 1 | F14: מקור | G14: רגיל | I14: אישור | J14: פרדר | K14: נתן | L14: 6888 | M14: תאריך שרות שונה בהתא | O14: 1116 | P14: 4463 | Q14: 223 | R14: 0 | T14: 45658 | V14: 203 | W14: 203 | X14: 45697
A15: 25155235 | B15: 45663 | C15: 45664 | D15: 2 | E15: 1 | F15: מקור | G15: רגיל | I15: אישור | J15: פרדר | K15: נתן | L15: 6888 | M15: תאריך שרות שונה בהתא | O15: 2231 | P15: 4463 | Q15: 446 | R15: 0 | T15: 45658 | V15: 203 | W15: 203 | X15: 45697
A16: 25155235 | B16: 45665 | C16: 45666 | D16: 2 | E16: 1 | F16: מקור | G16: רגיל | I16: אישור | J16: פרדר | K16: נתן | L16: 6888 | M16: תאריך שרות שונה בהתא | O16: 2231 | P16: 4463 | Q16: 446 | R16: 0 | T16: 45658 | V16: 203 | W16: 203 | X16: 45697
A17: 25155235 | B17: 45673 | C17: 45674 | D17: 2 | E17: 1 | F17: מקור | G17: רגיל | I17: אישור | J17: פרדר | K17: נתן | L17: 6888 | M17: תאריך שרות שונה בהתא | O17: 2231 | P17: 1116 | Q17: 446 | R17: 0 | T17: 45658 | V17: 203 | W17: 203 | X17: 45697
A18: 25155235 | B18: 45671 | C18: 45672 | D18: 2 | E18: 1 | F18: מקור | G18: רגיל | I18: אישור | J18: פרדר | K18: נתן | O18: 2231 | P18: 2231 | Q18: 446 | R18: 0 | T18: 45658 | V18: 203 | W18: 203 | X18: 45697
A19: 25155235 | B19: 45677 | C19: 45677 | D19: 1 | E19: 1 | F19: מקור | G19: רגיל | I19: אישור | J19: פרדר | K19: נתן | O19: 1116 | P19: 1116 | Q19: 223 | R19: 0 | T19: 45658 | V19: 203 | W19: 203 | X19: 45697
A20: 25155235 | B20: 45681 | C20: 45681 | D20: 1 | E20: 1 | F20: מקור | G20: רגיל | I20: אישור | J20: פרדר | K20: נתן | L20: 6888 | M20: תאריך שרות שונה בהתא | O20: 1116 | P20: 3347 | Q20: 223 | R20: 0 | T20: 45658 | V20: 203 | W20: 203 | X20: 45697
A21: 25155235 | B21: 14/01/2025 | C21: 17/01/2025 | D21: 4 | E21: 4 | I21: תוספת | J21: פרדר | K21: נתן | S21: 1795 | T21: 45658 | V21: 203 | W21: 410 | X21: 45775
A22: 25155235 | B22: 20/01/2025 | C22: 20/01/2025 | D22: 1 | E22: 1 | I22: תוספת | J22: פרדר | K22: נתן | S22: 449 | T22: 45658 | V22: 203 | W22: 410 | X22: 45775
A23: 28027738 | B23: 45658 | C23: 45660 | D23: 3 | E23: 1 | F23: מקור | G23: רגיל | I23: אישור | J23: מלח | K23: אייל | O23: 2206 | P23: 2778 | Q23: 556 | R23: 0 | T23: 45658 | V23: 203 | W23: 203 | X23: 45697
A24: 203661004 | B24: 45676 | C24: 45679 | D24: 4 | E24: 1 | F24: מקור | G24: רגיל | I24: אישור | J24: אליה | K24: אריאל | O24: 3710 | P24: 2529 | Q24: 506 | R24: 0 | T24: 45658 | V24: 203 | W24: 204 | X24: 45700
A25: 308280510 | B25: 45679 | C25: 45687 | D25: 9 | E25: 1 | F25: מקור | G25: רגיל | I25: אישור | J25: לוי | K25: דור | O25: 6992 | P25: 5965 | Q25: 1193 | R25: 0 | T25: 45658 | V25: 203 | W25: 204 | X25: 45700
A26: 315919936 | B26: 45683 | C26: 45687 | D26: 5 | E26: 1 | F26: מקור | G26: רגיל | I26: אישור | J26: בנדרימר | K26: דניאל | O26: 3981 | P26: 2550 | Q26: 510 | R26: 0 | T26: 45658 | V26: 203 | W26: 204 | X26: 45700
A27: 11915519 | B27: 45712 | C27: 45716 | D27: 5 | E27: 1 | F27: מקור | G27: רגיל | I27: אישור | J27: מרקוביץ' | K27: מנפרד | O27: 7184 | P27: 6082 | Q27: 1217 | R27: 0 | T27: 45717 | W27: 408 | X27: 45770
A28: 11915519 | B28: 45735 | C28: 45736 | D28: 2 | E28: 1 | F28: מקור | G28: רגיל | I28: אישור | J28: מרקוביץ' | K28: מנפרד | O28: 2873 | P28: 2404 | Q28: 481 | R28: 0 | T28: 45717 | W28: 408 | X28: 45770
A29: 11915519 | B29: 45742 | C29: 45742 | D29: 1 | E29: 1 | F29: מקור | G29: רגיל | I29: אישור | J29: מרקוביץ' | K29: מנפרד | O29: 1437 | P29: 1202 | Q29: 240 | R29: 0 | T29: 45717 | W29: 408 | X29: 45770
A30: 22201347 | B30: 45698 | C30: 45698 | D30: 1 | E30: 1 | F30: מקור | G30: רגיל | I30: אישור | J30: שלמה | K30: יורם | O30: 1174 | P30: 1174 | Q30: 235 | R30: 0 | T30: 45717 | W30: 408 | X30: 45770
A31: 22201347 | B31: 45706 | C31: 45707 | D31: 2 | E31: 1 | F31: מקור | G31: רגיל | I31: אישור | J31: שלמה | K31: יורם | O31: 3287 | P31: 2348 | Q31: 470 | R31: 0 | T31: 45717 | W31: 408 | X31: 45770
A32: 22201347 | B32: 45714 | C32: 45714 | D32: 1 | E32: 1 | F32: מקור | G32: רגיל | I32: אישור | J32: שלמה | K32: יורם | O32: 1174 | P32: 1174 | Q32: 235 | R32: 0 | T32: 45717 | W32: 408 | X32: 45770
A33: 22201347 | B33: 45720 | C33: 45720 | D33: 1 | E33: 1 | F33: מקור | G33: רגיל | I33: אישור | J33: שלמה | K33: יורם | O33: 1233 | P33: 1233 | Q33: 247 | R33: 0 | T33: 45717 | W33: 408 | X33: 45770
A34: 22201347 | B34: 45734 | C34: 45735 | D34: 2 | E34: 1 | F34: מקור | G34: רגיל | I34: אישור | J34: שלמה | K34: יורם | L34: 6888 | M34: תאריך שרות שונה בהתא | O34: 2466 | P34: 2466 | Q34: 493 | R34: 0 | T34: 45717 | W34: 408 | X34: 45770
A35: 22201347 | B35: 45733 | C35: 45733 | D35: 1 | E35: 1 | F35: מקור | G35: רגיל | I35: אישור | J35: שלמה | K35: יורם | L35: 6888 | M35: תאריך שרות שונה בהתא | O35: 1233 | P35: 2466 | Q35: 247 | R35: 0 | T35: 45717 | W35: 408 | X35: 45770
A36: 22201347 | B36: 45746 | C36: 45747 | D36: 2 | E36: 1 | F36: מקור | G36: רגיל | I36: אישור | J36: שלמה | K36: יורם | O36: 2466 | P36: 2466 | Q36: 493 | R36: 0 | T36: 45717 | W36: 408 | X36: 45770
A37: 25147505 | B37: 45711 | C37: 45711 | D37: 1 | E37: 1 | F37: מקור | G37: רגיל | I37: אישור | J37: בורך | K37: משה | O37: 1107 | P37: 791 | Q37: 158 | R37: 0 | T37: 45717 | W37: 408 | X37: 45770
