Workbook

Sheet רשימות
A1: חודשי תשלום
A2: 01/2025
A3: 02/2025
A4: 03/2025
A5: 04/2025
A6: 05/2025
A7: 06/2025
A8: 07/2025
A9: 08/2025
A10: 09/2025
A11: 10/2025
A12: 11/2025
... A37: 12/2027

Sheet 📖 הוראות שימוש
A1: 🎯 מערכת ניהול תשלומי מילואים - ליטאי ניהול שירותים
A2: ═══════════════════════════════════════════════════════
A4: 📋 מבנה המערכת:
A5: ─────────────────
A6: ✅ גליון 1: רשימת עובדים - פרטי העובדים ותעריפים
A7: ✅ גליון 2: תקופות מילואים - כל תקופת מילואים בנפרד
A8: ✅ גליון 3: תשלומי ביטוח לאומי - תשלומים שהתקבלו
A9: ✅ גליון 4: דוח מסכם - סיכום אוטומטי לפי עובד וחודש
A11: ─────────────────────────────────────────────────────
A13: 🔄 תהליך עבודה:
A15: שלב 1️⃣ - מלא נתוני עובדים
A16: • גליון "רשימת עובדים"
... A89: • 'התקבל מב"ל' = סה"כ תשלומים שמתאימים לטווח התאריכים

Sheet 1️⃣ רשימת עובדים
A1: ת.ז. | B1: שם פרטי | C1: שם משפחה | D1: שם מלא | E1: מחלקה | F1: משכורת חודשית | G1: תעריף יומי | H1: בנק | I1: מספר חשבון | J1: סטטוס
B2: אוראל | C2: שווקי | D2: אוראל שווקי | E2: רפאל | G2: =F2/22 -> 0 | J2: פעיל
A3: 211877550 | B3: אוראל | C3: שווקי | D3: אוראל שווקי | E3: רפאל | F3: 18717 | G3: 863.72866 | J3: פעיל
A4: 37643772 | B4: אורי | C4: אשתר | D4: אורי אשתר | E4: מל"מ | F4: 24026 | G4: 1108.7217 | J4: פעיל
A5: 28027738 | B5: אייל | C5: מלח | D5: אייל מלח | E5: רפאל | F5: 20500 | G5: 946.00831 | J5: מ01.09.25
A6: 203661004 | B6: אריאל | C6: אליה | D6: אריאל אליה | E6: מל"מ | F6: 18828 | G6: 868.85095 | J6: פעיל
A7: 315919936 | B7: דניאל | C7: בנדרימר | D7: דניאל בנדרימר | E7: מל"מ | F7: 14532 | G7: 670.60452 | J7: פעיל
A8: 69304962 | B8: חיים | C8: ראש | D8: חיים ראש | E8: מל"מ | F8: 20586.6 | G8: 950.00461 | J8: פעיל
A9: 25474677 | B9: יום | C9: טוב מוסארי | D9: יום טוב מוסארי | E9: רוה"מ | F9: 27791 | G9: 1282.4642 | J9: מ01.06.25
A10: 22201347 | B10: יורם | C10: שלמה | D10: יורם שלמה | E10: רוה"מ | F10: 23754 | G10: 1096.1698 | J10: פעיל
A11: 322131285 | B11: יענקל | C11: מונטבולינסקי | D11: יענקל מונטבולינסקי | E11: רפאל | F11: 18077 | G11: 834.19474 | J11: פעיל
A12: 209501998 | B12: לאון | C12: שמייב | D12: לאון שמייב | E12: רוה"מ | F12: 15825 | G12: 730.27227 | J12: 01.07.2025
A13: 308280510 | B13: לוי | C13: דור | D13: לוי דור | E13: רפאל | F13: 17921 | G13: 826.99585 | J13: פעיל
A14: 11915519 | B14: מנפרד | C14: מרקוביץ' | D14: מנפרד מרקוביץ' | E14: רפאל | F14: 18822 | G14: 868.57407 | J14: פעיל
... A19: 32345035 | B19: רפאל | C19: שועה | D19: רפאל שועה | E19: מל"מ | F19: 17670 | G19: 815.41301 | J19: פעיל

Sheet 3️⃣ תשלומי ב"ל
A1: ת.ז. | B1: שם עובד | C1: תאריך התחלה | D1: תאריך סיום | E1: סוג תשלום | F1: תגמול ₪ | G1: פיצוי 20% ₪ | H1: תוספת 40% ₪ | I1: סה"כ לעובד ₪ | J1: מספר מנה | K1: תאריך תשלום | L1: קובץ מקור
A2: 11915519 | B2: מנפרד מרקוביץ' | C2: 07/01/2025 | D2: 07/01/2025 | E2: רגיל | F2: 821 | G2: 164 | H2: 0 | I2: 985 | J2: 203 | K2: 09/02/2025 | L2: PDF_מנה_0203
A3: 11915519 | B3: מנפרד מרקוביץ' | C3: 16/01/2025 | D3: 16/01/2025 | E3: רגיל | F3: 821 | G3: 164 | H3: 0 | I3: 985 | J3: 203 | K3: 09/02/2025 | L3: PDF_מנה_0203
A4: 22201347 | B4: יורם שלמה | C4: 01/01/2025 | D4: 01/01/2025 | E4: רגיל | F4: 1051 | G4: 210 | H4: 0 | I4: 1261 | J4: 203 | K4: 09/02/2025 | L4: PDF_מנה_0203
A5: 22201347 | B5: יורם שלמה | C5: 19/01/2025 | D5: 23/01/2025 | E5: רגיל | F5: 5257 | G5: 1051 | H5: 0 | I5: 6308 | J5: 203 | K5: 09/02/2025 | L5: PDF_מנה_0203
A6: 25147505 | B6: משה בורך | C6: 27/11/2024 | D6: 27/11/2024 | E6: רגיל | F6: 751 | G6: 0 | H6: 0 | I6: 751 | J6: 203 | K6: 09/02/2025 | L6: PDF_מנה_0203
A7: 25155235 | B7: נתן פרדר | C7: 05/01/2025 | D7: 05/01/2025 | E7: רגיל | F7: 1116 | G7: 223 | H7: 0 | I7: 1339 | J7: 203 | K7: 09/02/2025 | L7: PDF_מנה_0203
A8: 25155235 | B8: נתן פרדר | C8: 06/01/2025 | D8: 07/01/2025 | E8: רגיל | F8: 2231 | G8: 446 | H8: 0 | I8: 2677 | J8: 203 | K8: 09/02/2025 | L8: PDF_מנה_0203
A9: 25155235 | B9: נתן פרדר | C9: 08/01/2025 | D9: 09/01/2025 | E9: רגיל | F9: 2231 | G9: 446 | H9: 0 | I9: 2677 | J9: 203 | K9: 09/02/2025 | L9: PDF_מנה_0203
A10: 25155235 | B10: נתן פרדר | C10: 10/01/2025 | D10: 11/01/2025 | E10: רגיל | F10: 2231 | G10: 446 | H10: 0 | I10: 2677 | J10: 203 | K10: 09/02/2025 | L10: PDF_מנה_0203
A11: 25155235 | B11: נתן פרדר | C11: 14/01/2025 | D11: 15/01/2025 | E11: רגיל | F11: 2231 | G11: 446 | H11: 0 | I11: 2677 | J11: 203 | K11: 09/02/2025 | L11: PDF_מנה_0203
A12: 25155235 | B12: נתן פרדר | C12: 16/01/2025 | D12: 17/01/2025 | E12: רגיל | F12: 1116 | G12: 446 | H12: 0 | I12: 1562 | J12: 203 | K12: 09/02/2025 | L12: PDF_מנה_0203
A13: 25155235 | B13: נתן פרדר | C13: 20/01/2025 | D13: 20/01/2025 | E13: רגיל | F13: 1116 | G13: 223 | H13: 0 | I13: 1339 | J13: 203 | K13: 09/02/2025 | L13: PDF_מנה_0203
... A81: 22201347 | B81: יורם שלמה | C81: 15/12/2024 | D81: 19/12/2024 | E81: תוספת 40% | F81: 0 | G81: 0 | H81: 3269 | I81: 3295 | J81: 510 | K81: 23/05/2025 | L81: 92437586800_NK-0510-250519-509_-1363229539_10591_0_01.xlsx

Sheet 4️⃣ דוח מסכם
A1: שם עובד | B1: מחלקה | C1: חודש | D1: תאריך התחלה מוקדם ביותר | E1: תאריך סיום מאוחר ביותר | F1: מספר תקופות | G1: סה"כ ימים | H1: ימי א-ה | I1: ימי סופ"ש | J1: צפוי מב"ל | K1: התקבל מב"ל | L1: הפרש | M1: סטטוס | N1: מזהי תקופות | O1: מזהי תקופות
A2: אוראל שווקי | C2: 03/2025 | D2: 19/03/2025 | E2: 19/03/2025 | F2: 1 | G2: 1 | H2: 1 | I2: 0 | J2: 876 | K2: 873 | L2: =K2-J2 -> -3 | O2: P0001
A3: אורי אשתר | C3: 09/2025 | D3: 01/09/2025 | E3: 17/09/2025 | F3: 1 | G3: 17 | H3: 13 | I3: 4 | K3: 15431 | O3: P0002
A4: אורי אשתר | C4: 45931 | D4: 45943 | E4: 45943 | G4: 1 | K4: 1042
A5: אייל מלח | C5: 01/2025 | D5: 01/01/2025 | E5: 03/01/2025 | F5: 1 | G5: 3 | H5: 3 | I5: 0 | J5: 2403.18 | K5: 2206 | L5: =K5-J5 -> -197.18 | M5: מרכז | O5: P0003
A6: אייל מלח | C6: 05/2025 | D6: 19/05/2025 | E6: 21/05/2025 | F6: 1 | G6: 3 | H6: 3 | I6: 0 | J6: =801.06*H6 -> 2403.18 | K6: 2408 | L6: =K6-J6 -> 4.82 | M6: מרכז | O6: P0004
A7: אייל מלח | C7: 06/2025 | D7: 12/06/2025 | E7: 26/06/2025 | F7: 1 | G7: 15 | H7: 11 | I7: 4 | J7: =801.06*H7 -> 8811.66 | K7: 12039 | L7: =K7-J7 -> 3227.34 | M7: מרכז | O7: P0005
A8: אייל מלח | C8: 07/2025 | D8: 29/07/2025 | E8: 31/07/2025 | F8: 1 | G8: 3 | H8: 3 | I8: 0 | J8: =801.06*H8 -> 2403.18 | K8: 2409 | L8: =K8-J8 -> 5.82 | M8: מרכז | O8: P0006
A9: אייל מלח | C9: 09/2025 | D9: 11/09/2025 | E9: 14/09/2025 | F9: 1 | G9: 4 | H9: 2 | I9: 2 | J9: =801.06*H9 -> 1602.12 | K9: 1284 | L9: =K9-J9 -> -318.12 | M9: מרכז | O9: P0007
A10: אריאל אליה | C10: 01/2025 | D10: 19/01/2025 | E10: 22/01/2025 | F10: 1 | G10: 4 | H10: 3 | I10: 1 | K10: 0 | O10: P0008
A11: אריאל אליה | C11: 03/2025 | D11: 02/03/2025 | E11: 05/03/2025 | F11: 1 | G11: 4 | H11: 3 | I11: 1 | K11: 3739 | O11: P0009
A12: אריאל אליה | C12: 04/2025 | D12: 23/04/2025 | E12: 27/04/2025 | F12: 2 | G12: 2 | H12: 1 | I12: 1 | K12: =967+967 -> 1934 | O12: P0010, P0011
A13: אריאל אליה | C13: 05/2025 | D13: 04/05/2025 | E13: 24/05/2025 | F13: 1 | G13: 21 | H13: 15 | I13: 6 | K13: 14425 | O13: P0012
A14: אריאל אליה | C14: 08/2025 | D14: 17/08/2025 | E14: 21/08/2025 | F14: 1 | G14: 5 | H14: 4 | I14: 1 | K14: 4673 | O14: P0013
A15: דניאל בנדרימר | C15: 01/2025 | D15: 26/01/2025 | E15: 30/01/2025 | F15: 1 | G15: 5 | H15: 4 | I15: 1 | K15: 0 | O15: P0014
A16: דניאל בנדרימר | C16: 04/2025 | D16: 22/04/2025 | E16: 29/05/2025 | F16: 1 | G16: 38 | H16: 28 | I16: 10 | K16: =5078+16362 -> 21440 | O16: P0015
A17: דניאל בנדרימר | C17: 06/2025 | D17: 03/06/2025 | E17: 30/06/2025 | F17: 1 | G17: 28 | H17: 20 | I17: 8 | K17: 15114 | O17: P0016
A18: דניאל בנדרימר | C18: 07/2025 | D18: 07/07/2025 | E18: 28/07/2025 | F18: 2 | G18: 3 | H18: 2 | I18: 1 | K18: =540+1080 -> 1620 | O18: P0017, P0018
A19: דניאל בנדרימר | C19: 08/2025 | D19: 06/08/2025 | E19: 07/08/2025 | F19: 1 | G19: 2 | H19: 2 | I19: 0 | K19: 0 | O19: P0019
A20: דניאל בנדרימר | C20: 09/2025 | D20: 09/09/2025 | E20: 30/09/2025 | F20: 2 | G20: 4 | H20: 4 | I20: 0 | K20: 0 | O20: P0020, P0021
A21: חיים ראש | C21: 06/2025 | D21: 05/06/2025 | E21: 05/06/2025 | F21: 1 | G21: 1 | H21: 1 | I21: 0 | K21: 1497 | O21: P0022
A22: יום טוב מוסארי | C22: 02/2025 | D22: 20/02/2025 | E22: 23/02/2025 | F22: 2 | G22: 2 | H22: 1 | I22: 1 | K22: 0 | O22: P0023, P0024
A23: יום טוב מוסארי | C23: 06/2025 | D23: 12/06/2025 | E23: 29/06/2025 | F23: 1 | G23: 18 | H23: 12 | I23: 6 | K23: =5458+1624 -> 7082 | O23: P0025
A24: יורם שלמה | C24: 01/2025 | D24: 01/01/2025 | E24: 23/01/2025 | F24: 2 | G24: 6 | H24: 5 | I24: 1 | K24: 5819 | O24: P0026, P0027
A25: יורם שלמה | C25: 02/2025 | D25: 10/02/2025 | E25: 26/02/2025 | F25: 3 | G25: 4 | H25: 4 | I25: 0 | K25: 4635 | O25: P0028, P0029, P0030
A26: יורם שלמה | C26: 03/2025 | D26: 04/03/2025 | E26: 03/04/2025 | F26: 3 | G26: 9 | H26: 8 | I26: 1 | K26: 6038 | O26: P0031, P0032, P0033
A27: יורם שלמה | C27: 04/2025 | D27: 09/04/2025 | E27: 10/04/2025 | F27: 1 | G27: 2 | H27: 2 | I27: 0 | K27: 6268 | O27: P0034
A28: יורם שלמה | C28: 05/2025 | D28: 05/05/2025 | E28: 28/05/2025 | F28: 3 | G28: 6 | H28: 6 | I28: 0 | K28: 7821 | O28: P0035, P0036, P0037
A29: יורם שלמה | C29: 06/2025 | D29: 05/06/2025 | E29: 12/06/2025 | F29: 2 | G29: 3 | H29: 3 | I29: 0 | K29: 6268 | O29: P0038, P0039
A30: יורם שלמה | C30: 07/2025 | D30: 28/07/2025 | E30: 31/07/2025 | F30: 1 | G30: 4 | H30: 4 | I30: 0 | K30: 6268 | O30: P0040
A31: יורם שלמה | C31: 09/2025 | D31: 17/09/2025 | E31: 17/09/2025 | F31: 1 | G31: 2 | H31: 2 | I31: 0 | K31: 3038 | L31: 1898 זה היה בטבלה של ביטוח לאומי | O31: P0041
A32: יורם שלמה | C32: 45931 | D32: 21/20/2025 | E32: 45952 | G32: 2 | K32: 899
A33: יענקל מונטבולינסקי | C33: 07/2025 | D33: 21/07/2025 | E33: 30/07/2025 | F33: 3 | G33: 6 | H33: 6 | I33: 0 | K33: =450+899+1348 -> 2697 | O33: P0042, P0043, P0044
A34: יענקל מונטבולינסקי | C34: 08/2025 | D34: 04/08/2025 | E34: 12/08/2025 | F34: 3 | G34: 3 | H34: 3 | I34: 0 | K34: 0 | O34: P0045, P0046, P0047
A35: יענקל מונטבולינסקי | C35: 09/2025 | D35: 15/09/2025 | E35: 21/09/2025 | F35: 2 | G35: 3 | H35: 2 | I35: 1 | K35: 0 | O35: P0048, P0049
A36: לאון שמייב | C36: 03/2025 | D36: 24/03/2025 | E36: 24/03/2025 | F36: 1 | G36: 1 | H36: 1 | I36: 0 | K36: 853 | O36: P0050
A37: לאון שמייב | C37: 05/2025 | D37: 25/05/2025 | E37: 27/05/2025 | F37: 1 | G37: 3 | H37: 2 | I37: 1 | K37: 2605 | O37: P0051
A38: לאון שמייב | C38: 06/2025 | D38: 16/06/2025 | E38: 23/06/2025 | F38: 1 | G38: 8 | H38: 6 | I38: 2 | K38: 4961 | O38: P0052
A39: לאון שמייב | C39: 07/2025 | D39: 27/07/2025 | E39: 29/07/2025 | F39: 1 | G39: 3 | H39: 2 | I39: 1 | K39: 2546 | O39: P0053
A40: לאון שמייב | C40: 08/2025 | D40: 17/08/2025 | E40: 20/08/2025 | F40: 1 | G40: 4 | H40: 3 | I40: 1 | K40: 3350 | O40: P0054
...

Sheet 💵 רשימת תשלומים
A1: מנה | B1: תאריך תשלום | C1: תגמול ₪ | D1: פיצוי 20% ₪ | E1: תוספת 40% ₪ | F1: סה"כ כולל ₪ | G1: ביקורת נתונים מול תקופות מילואים
A2: 203 | B2: 09/02/2025 | C2: 48622 | D2: 8587 | E2: 0 | F2: 57209
A3: 204 | B3: 09/02/2025 | C3: 581 | D3: 0 | E3: 0 | F3: 581
A4: 408 | B4: 23/04/2025 | C4: 25634 | D4: 4516 | E4: 0 | F4: 30150
A5: 410 | B5: 28/04/2025 | C5: 0 | D5: 0 | E5: 6209 | F5: =SUM(C5:E5) -> 6209 | G5: תקין
B6: 45777 | C6: 103440 | D6: =15441+257 -> 15698 | F6: =SUM(C6:E6) -> 119138
A7: 510 | B7: 23/05/2025 | C7: 0 | D7: 0 | E7: 19639 | F7: =SUM(C7:E7) -> 19639
A8: 610 | B8: 26/06/2025 | C8: 0 | D8: 0 | E8: 4389 | F8: =SUM(C8:E8) -> 4389 | G8: תקין
A9: 802 | B9: 08/08/2025 | C9: 112299 | D9: 21358 | E9: 0 | F9: =SUM(C9:E9) -> 133657 | G9: תקין
A11: סה"כ: | C11: =SUM(C2:C10) -> 290576 | D11: =SUM(D2:D10) -> 50159 | E11: =SUM(E2:E10) -> 30237 | F11: =SUM(F2:F10) -> 370972

Sheet 2️⃣ תקופות מילואים
A1: מזהה תקופה | B1: שם עובד | C1: מחלקה | D1: תאריך התחלה | E1: תאריך סיום | F1: חודש | G1: סה"כ ימים | H1: ימי א-ה | I1: ימי שישי | J1: ימי שבת | K1: ימי חג | L1: תעריף יומי | M1: תשלום מעסיק (א-ה) | N1: פיצוי 20% למעסיק | O1: תוספת 40% | P1: סה"כ תגמול מביטוח לאומי ₪ | Q1: מועד תשלום ביטוח לאומי | R1: סכום הפרשים לעובד ₪ | S1: חודש ביצוע תשלום | T1: 💰 הערות
A2: P0001 | B2: אוראל שווקי | C2: רפאל | D2: 45735 | E2: 45735 | F2: 03/2025 | G2: 1 | H2: 1 | I2: 0 | J2: 0 | K2: 0 | L2: 863.72866 | M2: =L2*H2 -> 863.72866 | N2: 172.74573
A3: P0002 | B3: אורי אשתר | C3: מל"מ | D3: 45901 | E3: 45917 | F3: 09/2025 | G3: 17 | H3: 13 | I3: 2 | J3: 2 | K3: 0 | L3: 1108.7217 | M3: =L3*H3 -> 14413.383 | N3: 2882.6765
A4: P0003 | B4: אייל מלח | C4: רפאל | D4: 45658 | E4: 45660 | F4: 01/2025 | G4: 3 | H4: 3 | I4: 0 | J4: 0 | K4: 0 | L4: 806.01 | M4: =L4*H4 -> 2418.03 | N4: 556 | P4: 2206 | Q4: 45697
A5: P0004 | B5: אייל מלח | C5: רפאל | D5: 45796 | E5: 45798 | F5: 05/2025 | G5: 3 | H5: 3 | I5: 0 | J5: 0 | K5: 0 | L5: 806.01 | M5: =L5*H5 -> 2418.03
A6: P0005 | B6: אייל מלח | C6: רפאל | D6: 45820 | E6: 45834 | F6: 06/2025 | G6: 15 | H6: 11 | I6: 2 | J6: 2 | K6: 0 | L6: 806.01 | M6: =L6*H6 -> 8866.11
A7: P0006 | B7: אייל מלח | C7: רפאל | D7: 45867 | E7: 45869 | F7: 07/2025 | G7: 3 | H7: 3 | I7: 0 | J7: 0 | K7: 0 | L7: 806.01 | M7: =L7*H7 -> 2418.03
A8: P0007 | B8: אייל מלח | C8: רפאל | D8: 45911 | E8: 45914 | F8: 09/2025 | G8: 4 | H8: 2 | I8: 1 | J8: 1 | K8: 0 | L8: ='📈 היסטוריית שכר'!C6 -> 1108.7217 | M8: =L8*H8 -> 2217.4435
A9: P0008 | B9: אריאל אליה | C9: מל"מ | D9: 45676 | E9: 45679 | F9: 01/2025 | G9: 4 | H9: 3 | I9: 0 | J9: 1 | K9: 0 | L9: 868.85095 | M9: =L9*H9 -> 2606.5528 | N9: 506 | P9: 3710 | Q9: 45700
A10: P0009 | B10: אריאל אליה | C10: מל"מ | D10: 45718 | E10: 45721 | F10: 03/2025 | G10: 4 | H10: 3 | I10: 0 | J10: 1 | K10: 0 | L10: 868.85095 | M10: =L10*H10 -> 2606.5528 | N10: 518 | P10: 3739 | Q10: 45988
A11: P0010 | B11: אריאל אליה | C11: מל"מ | D11: 45770 | E11: 45770 | F11: 04/2025 | G11: 1 | H11: 1 | I11: 0 | J11: 0 | K11: 0 | L11: 868.85095 | M11: =L11*H11 -> 868.85095 | N11: 138 | P11: 967 | Q11: 45988 | R11: =O11 -> 0 | S11: 45809
A12: P0011 | B12: אריאל אליה | C12: מל"מ | D12: 45774 | E12: 45774 | F12: 04/2025 | G12: 1 | H12: 0 | I12: 0 | J12: 1 | K12: 0 | L12: 868.85095 | M12: =L12*H12 -> 0 | N12: 138 | P12: 967 | Q12: 45988
A13: P0012 | B13: אריאל אליה | C13: מל"מ | D13: 45781 | E13: 45801 | F13: 05/2025 | G13: 21 | H13: 15 | I13: 3 | J13: 3 | K13: 0 | L13: 868.85095 | M13: =L13*H13 -> 13032.764 | N13: 2885 | P13: 14425 | Q13: 45988 | R13: =O13 -> 0 | S13: 45809
A14: P0013 | B14: אריאל אליה | C14: מל"מ | D14: 45886 | E14: 45890 | F14: 08/2025 | G14: 5 | H14: 4 | I14: 0 | J14: 1 | K14: 0 | L14: 868.85095 | M14: =L14*H14 -> 3475.4038 | N14: 657 | P14: 4673 | Q14: 45988
A15: P0014 | B15: דניאל בנדרימר | C15: מל"מ | D15: 45683 | E15: 45687 | F15: 01/2025 | G15: 5 | H15: 4 | I15: 0 | J15: 1 | K15: 0 | L15: 670.60452 | M15: =L15*H15 -> 2682.4181 | N15: 510 | P15: 3981 | Q15: 45700
A16: P0015 | B16: דניאל בנדרימר | C16: מל"מ | D16: 45769 | E16: 45806 | F16: 04/2025 | G16: 38 | H16: 28 | I16: 5 | J16: 5 | K16: 0 | L16: 670.60452 | M16: =L16*H16 -> 18776.927 | N16: 3755.3853
A17: P0016 | B17: דניאל בנדרימר | C17: מל"מ | D17: 45811 | E17: 45838 | F17: 06/2025 | G17: 28 | H17: 20 | I17: 4 | J17: 4 | K17: 0 | L17: 670.60452 | M17: =L17*H17 -> 13412.09 | N17: 2682.4181
A18: P0017 | B18: דניאל בנדרימר | C18: מל"מ | D18: 45845 | E18: 45845 | F18: 07/2025 | G18: 1 | H18: 1 | I18: 0 | J18: 0 | K18: 0 | L18: 670.60452 | M18: =L18*H18 -> 670.60452 | N18: 134.1209
A19: P0018 | B19: דניאל בנדרימר | C19: מל"מ | D19: 45865 | E19: 45866 | F19: 07/2025 | G19: 2 | H19: 1 | I19: 0 | J19: 1 | K19: 0 | L19: 670.60452 | M19: =L19*H19 -> 670.60452 | N19: 134.1209
A20: P0019 | B20: דניאל בנדרימר | C20: מל"מ | D20: 45875 | E20: 45876 | F20: 08/2025 | G20: 2 | H20: 2 | I20: 0 | J20: 0 | K20: 0 | L20: 670.60452 | M20: =L20*H20 -> 1341.209 | N20: 268.24181
A21: P0020 | B21: דניאל בנדרימר | C21: מל"מ | D21: 45909 | E21: 45911 | F21: 09/2025 | G21: 3 | H21: 3 | I21: 0 | J21: 0 | K21: 0 | L21: 670.60452 | M21: =L21*H21 -> 2011.8136 | N21: 402.36271
A22: P0021 | B22: דניאל בנדרימר | C22: מל"מ | D22: 45930 | E22: 45930 | F22: 09/2025 | G22: 1 | H22: 1 | I22: 0 | J22: 0 | K22: 0 | L22: 670.60452 | M22: =L22*H22 -> 670.60452 | N22: 134.1209
A23: P0022 | B23: חיים ראש | C23: מל"מ | D23: 45813 | E23: 45813 | F23: 06/2025 | G23: 1 | H23: 1 | I23: 0 | J23: 0 | K23: 0 | L23: 950.00461 | M23: =L23*H23 -> 950.00461 | N23: 190.00092
A24: P0023 | B24: יום טוב מוסארי | C24: רוה"מ | D24: 45708 | E24: 45708 | F24: 02/2025 | G24: 1 | H24: 1 | I24: 0 | J24: 0 | K24: 0 | L24: 1282.4642 | M24: =L24*H24 -> 1282.4642 | N24: 256.49285
A25: P0024 | B25: יום טוב מוסארי | C25: רוה"מ | D25: 45711 | E25: 45711 | F25: 02/2025 | G25: 1 | H25: 0 | I25: 0 | J25: 1 | K25: 0 | L25: 1282.4642 | M25: =L25*H25 -> 0 | N25: 0
A26: P0025 | B26: יום טוב מוסארי | C26: רוה"מ | D26: 45820 | E26: 45837 | F26: 06/2025 | G26: 18 | H26: 12 | I26: 3 | J26: 3 | K26: 0 | L26: 1282.4642 | M26: =L26*H26 -> 15389.571 | N26: 3077.9142
A27: P0026 | B27: יורם שלמה | C27: רוה"מ | D27: 45658 | E27: 45658 | F27: 01/2025 | G27: 1 | H27: 1 | I27: 0 | J27: 0 | K27: 0 | L27: 1096.1698 | M27: =L27*H27 -> 1096.1698 | N27: 210 | P27: =1051+615 -> 1666 | Q27: 45697
B28: יורם שלמה | C28: רוה"מ | D28: 45658 | E28: 45658 | F28: 01/2025 | G28: 1 | H28: 1 | I28: 0 | J28: 0 | K28: 0 | O28: 420 | Q28: 45775
A29: P0027 | B29: יורם שלמה | C29: רוה"מ | D29: 45676 | E29: 45680 | F29: 01/2025 | G29: 5 | H29: 4 | I29: 0 | J29: 1 | K29: 0 | L29: 1096.1698 | M29: =L29*H29 -> 4384.6793 | N29: 1051 | P29: =5257+3073 -> 8330 | Q29: 45697
B30: יורם שלמה | C30: רוה"מ | D30: 45676 | E30: 45680 | F30: 01/2025 | G30: 5 | H30: 4 | I30: 0 | J30: 1 | K30: 0 | O30: 2103 | Q30: 45775
A31: P0028 | B31: יורם שלמה | C31: רוה"מ | D31: 45698 | E31: 45698 | F31: 02/2025 | G31: 1 | H31: 1 | I31: 0 | J31: 0 | K31: 0 | L31: 1096.1698 | M31: =L31*H31 -> 1096.1698 | P31: =492+1174 -> 1666 | Q31: 45777
B32: יורם שלמה | C32: רוה"מ | D32: 45698 | E32: 45698 | F32: 02/2025 | G32: 1 | H32: 0 | I32: 0 | J32: 0 | K32: 0 | O32: 666 | Q32: 45800
A33: P0029 | B33: יורם שלמה | C33: רוה"מ | D33: 45706 | E33: 45707 | F33: 02/2025 | G33: 2 | H33: 2 | I33: 0 | J33: 0 | K33: 0 | L33: 1096.1698 | M33: =L33*H33 -> 2192.3396 | N33: 470 | P33: =1378+3287 -> 4665 | Q33: 45777
A34: P0030 | B34: יורם שלמה | C34: רוה"מ | D34: 45714 | E34: 45714 | F34: 02/2025 | G34: 1 | H34: 1 | I34: 0 | J34: 0 | K34: 0 | L34: 1096.1698 | M34: =L34*H34 -> 1096.1698 | N34: 247 | P34: =492+1174 -> 1666 | Q34: 45777
B35: יורם שלמה | C35: רוה"מ | D35: 45714 | E35: 45714 | F35: 02/2025 | G35: 1 | H35: 1 | I35: 0 | J35: 0 | K35: 0 | O35: 666 | Q35: 45800
A36: P0031 | B36: יורם שלמה | C36: רוה"מ | D36: 45720 | E36: 45720 | F36: 03/2025 | G36: 1 | H36: 1 | I36: 0 | J36: 0 | K36: 0 | L36: 1096.1698 | M36: =L36*H36 -> 1096.1698 | N36: 247 | P36: =433+1233 -> 1666 | Q36: 45777
B37: יורם שלמה | C37: רוה"מ | D37: 45720 | E37: 45720 | F37: 03/2025 | G37: 1 | H37: 1 | I37: 0 | J37: 0 | K37: 0 | O37: 666 | Q37: 45834
A38: P0032 | B38: יורם שלמה | C38: רוה"מ | D38: 45733 | E38: 45735 | F38: 03/2025 | G38: 3 | H38: 3 | I38: 0 | J38: 0 | K38: 0 | L38: 1096.1698 | M38: =L38*H38 -> 3288.5095 | N38: =493+247 -> 740 | P38: =866+433+1233+2466 -> 4998 | Q38: 45834
B39: יורם שלמה | C39: רוה"מ | D39: 45733 | E39: 45735 | F39: 03/2025 | G39: 3 | H39: 3 | I39: 0 | J39: 0 | K39: 0 | O39: 1999 | Q39: 45834
A40: P0033 | B40: יורם שלמה | C40: רוה"מ | D40: 45746 | E40: 45747 | F40: 03/2025 | G40: 2 | H40: 4 | I40: 0 | J40: 1 | K40: 0 | L40: 1096.1698 | M40: =L40*H40 -> 4384.6793 | N40: 493 | P40: =866+2466 -> 3332 | Q40: 45777
...

Sheet 📈 היסטוריית שכר
A1: 📈 היסטוריית שכר - מעקב אחר שינויי תעריפים
A2: 💡 כל שינוי בתעריף יומי מתועד כאן. המערכת תשתמש בתעריף הנכון לפי תאריך השירות.
A4: ת.ז. | B4: שם מלא | C4: תעריף יומי ₪ | D4: תעריף חודשי ₪ | E4: תקף מתאריך | F4: תקף עד תאריך | G4: סוג שינוי | H4: הערות
A5: 211877550 | B5: אוראל שווקי | C5: =D5/21.67 -> 922.93493 | D5: 20000 | E5: 45566 | G5: תעריף ראשוני
A6: 37643772 | B6: אורי אשתר | C6: =D6/21.67 -> 1108.7217 | D6: =(21250+2776) -> 24026 | E6: 45784 | G6: תעריף ראשוני
A7: 28027738 | B7: אייל מלח | C7: =D7/21.67 -> 883.7102 | D7: =(15350+2650+1150) -> 19150 | E7: 45292 | G7: תעריף ראשוני | H7: לפני העלאה
A8: 28027738 | B8: אייל מלח | C8: =D8/21.67 -> 946.00831 | D8: =(16400+4100) -> 20500 | E8: 01/09/2024 | G8: 🔺 העלאת שכר | H8: שינוי מספטמבר 2025
A9: 203661004 | B9: אריאל אליה | C9: 876.93 | D9: 19003 | E9: 01/01/2024 | G9: תעריף ראשוני
A10: 206092371 | B10: דניאל אולשנסקי | C10: =D10/21.67 -> 846.00831 | D10: =(15790+2543) -> 18333 | E10: 45658 | F10: 45991 | G10: תעריף ראשוני | H10: סיים ב30.11.2025
A11: 315919936 | B11: דניאל בנדרימר | C11: =D11/21.67 -> 670.2815 | D11: =13175+1350 -> 14525 | E11: 01/01/2024 | G11: תעריף ראשוני
A12: 69304962 | B12: חיים ראש | C12: =D12/21.67 -> 1084.4024 | D12: =(16954+3633+16*182) -> 23499 | E12: 01/01/2024 | G12: תעריף ראשוני | H12: כולל תוספת של 16 ₪ בהפרשים
A13: 25474677 | B13: יום טוב מוסארי | C13: =D13/21.67 -> 1180.1108 | D13: =21250+4323 -> 25573 | E13: 45292 | F13: 45808 | G13: תעריף ראשוני
A14: 25474677 | B14: יום טוב מוסארי | C14: =D14/21.67 -> 1282.4642 | D14: =(22750+5041) -> 27791 | E14: 45809 | G14: 🔺 העלאת שכר
A15: 22201347 | B15: יורם שלמה | C15: =D15/21.67 -> 1107.3373 | D15: 23996 | E15: 01/01/2024 | F15: 45961 | G15: תעריף ראשוני | H15: סיים ב31.10.2025
A16: 322131285 | B16: יענקל מונטבולינסקי | C16: =D16/21.67 -> 868.8048 | D16: =16150+817+1110+750 -> 18827 | E16: 45809 | G16: תעריף ראשוני
A17: 209501998 | B17: לאון שמייב | C17: 599.86 | D17: 13000 | E17: 45292 | F17: 45869 | G17: תעריף ראשוני
A18: 209501998 | B18: לאון שמייב | C18: =D18/21.67 -> 738.34795 | D18: 16000 | E18: 45870 | G18: 🔺 העלאת שכר
A19: 308280510 | B19: לוי דור | C19: 744.35 | D19: 16130 | E19: 01/01/2024 | G19: תעריף ראשוני
A20: 11915519 | B20: מנפרד מרקוביץ' | C20: 845.92 | D20: 18331 | E20: 01/01/2024 | F20: 45961 | G20: תעריף ראשוני
A21: 11915519 | B21: מנפרד מרקוביץ' | C21: =D21/21.67 -> 983.94093 | D21: =(18275+3047) -> 21322 | E21: 45962 | G21: 🔺 העלאת שכר
A22: 25147505 | B22: משה בורך | C22: 868.68 | D22: 18824 | E22: 01/01/2024 | F22: 45961 | G22: תעריף ראשוני
A23: 25147505 | B23: משה בורך | C23: =D23/21.67 -> 877.34195 | D23: =(17580+1432) -> 19012 | E23: 45962 | G23: 🔺 העלאת שכר
A24: 25155235 | B24: נתן פרדר | C24: =D24/21.67 -> 914.85925 | D24: =17000+2825 -> 19825 | E24: 45658 | G24: תעריף ראשוני
A25: 315536524 | B25: צחי חנגל | C25: =D25/21.67 -> 812.22889 | D25: =13430+3052+1119 -> 17601 | E25: 45292 | G25: תעריף ראשוני
A26: 25342445 | B26: משה פינץ | C26: =D26/21.67 -> 914.85925 | D26: =(17000+1657+1168) -> 19825 | E26: 45658 | F26: 45961 | G26: תעריף ראשוני | H26: סיים ב31.10.2025
A27: 32345035 | B27: רפאל שועה | C27: =D27/21.67 -> 815.41301 | D27: =(15725+1945) -> 17670 | E27: 45658 | G27: תעריף ראשוני
A28: 206184806 | B28: אבישי שרון מהדקאר | C28: =D28/21.67 -> 822.61191 | D28: =(15300+926+750+850) -> 17826 | E28: 45893 | G28: תעריף ראשוני
A29: 213026206 | B29: אורי דוד עברי | C29: =D29/21.67 -> 730.31841 | D29: =(13600+750+626+850) -> 15826 | E29: 45945 | G29: תעריף ראשוני
A30: 316048313 | B30: איתי קעטבי | C30: =D30/21.67 -> 1191.7859 | D30: =(22100+2176+750+800) -> 25826 | E30: 46001 | G30: תעריף ראשוני
A31: 324921550 | B31: נהיראל כהן | C31: =D31/21.67 -> 684.17167 | D31: =(12750+750+476+850) -> 14826 | E31: 45755 | G31: תעריף ראשוני
A32: 318763786 | B32: קומרוב ג'סיקה | C32: =D32/21.67 -> 692.2012 | D32: =(12000+3000) -> 15000 | E32: 45579 | G32: תעריף ראשוני
A33: 207384934 | B33: רום יחיא | C33: =D33/21.67 -> 776.64975 | D33: =(14450+1580+800) -> 16830 | E33: 45748 | G33: תעריף ראשוני

Sheet 2️⃣ תקופות מילואים-חדש
A1: ת"ז | B1: שם עובד | C1: מחלקה | D1: תאריך התחלה | E1: תאריך סיום | F1: חודש | G1: סה"כ ימים | H1: ימי א-ה | I1: ימי שישי | J1: ימי שבת | K1: ימי חג | L1: תעריף יומי | M1: תשלום מעסיק (א-ה) | N1: ב"ל לעובדתוספת 40% | O1: סה"כ תגמול מביטוח לאומי ₪ | P1: מועד תשלום ביטוח לאומי | Q1: סכום הפרשים לעובד ₪ | R1: שולם לעובד בשכר קודם | S1: חודש ביצוע תשלום | T1: 💰 הערות
A2: 211877550 | B2: אוראל שווקי | C2: רפאל | D2: 45735 | E2: 45735 | F2: 45717 | G2: 1 | H2: 1 | I2: 0 | J2: 0 | K2: 0 | L2: ='📈 היסטוריית שכר'!C5 -> 922.93493 | M2: =L2*H2 -> 922.93493 | O2: 873 | P2: 45988 | Q2: =O2-M2 -> -49.934933 | S2: 46023 | T2: שולי-- לא הייתי מחייבת
A3: 37643772 | B3: אורי אשתר | C3: מל"מ | D3: 45901 | E3: 45917 | F3: 45901 | G3: 17 | H3: 13 | I3: 2 | J3: 2 | K3: 0 | L3: ='📈 היסטוריית שכר'!C6 -> 1108.7217 | M3: =L3*H3 -> 14413.383 | N3: 1089 | O3: 15431 | P3: 45988 | Q3: =O3-M3+N3 -> 2106.6174 | S3: 46023
A4: 37643772 | B4: אורי אשתר | C4: מל"מ | D4: 45943 | E4: 45943 | F4: 45931 | G4: 1 | H4: 1 | I4: 0 | J4: 0 | K4: 0 | L4: 1109 | M4: =L4*H4 -> 1109 | O4: 1042 | P4: 45988 | Q4: =O4-M4 -> -67 | S4: 46023
A5: 28027738 | B5: אייל מלח | C5: רפאל | D5: 45658 | E5: 45660 | F5: 45658 | G5: 3 | H5: 2 | I5: 1 | J5: 0 | K5: 0 | L5: ='📈 היסטוריית שכר'!C7 -> 883.7102 | M5: =L5*H5 -> 1767.4204 | O5: 2403.19 | P5: 45700 | Q5: =O5-M5 -> 635.7696 | S5: 46023
A6: 28027738 | B6: אייל מלח | C6: רפאל | D6: 45796 | E6: 45798 | F6: 45778 | G6: 3 | H6: 3 | I6: 0 | J6: 0 | K6: 0 | L6: ='📈 היסטוריית שכר'!C8 -> 946.00831 | M6: =L6*H6 -> 2838.0249 | N6: 963 | O6: 2408 | P6: 45988 | Q6: =O6-M6+N6 -> 532.97508 | S6: 46023
A7: 28027738 | B7: אייל מלח | C7: רפאל | D7: 45820 | E7: 45834 | F7: 45809 | G7: 15 | H7: 11 | I7: 2 | J7: 2 | K7: 0 | L7: ='📈 היסטוריית שכר'!C9 -> 876.93 | M7: =L7*H7 -> 9646.23 | N7: 321 | O7: 12039 | P7: 45988 | Q7: =O7-M7+N7 -> 2713.77 | S7: 46023
A8: 28027738 | B8: אייל מלח | C8: רפאל | D8: 45867 | E8: 45869 | F8: 45839 | G8: 3 | H8: 3 | I8: 0 | J8: 0 | K8: 0 | L8: ='📈 היסטוריית שכר'!C10 -> 846.00831 | M8: =L8*H8 -> 2538.0249 | N8: 964 | O8: 2409 | P8: 45988 | Q8: =O8-M8+N8 -> 834.97508 | S8: 46023
A9: 28027738 | B9: אייל מלח | C9: רפאל | D9: 45911 | E9: 45914 | F9: 45901 | G9: 4 | H9: 2 | I9: 1 | J9: 1 | K9: 0 | L9: ='📈 היסטוריית שכר'!C8 -> 946.00831 | M9: =L9*H9 -> 1892.0166 | N9: 514 | O9: 1284 | P9: 45988 | Q9: =O9-M9+N9 -> -94.016613 | S9: 46023
A10: 203661004 | B10: אריאל אליה | C10: מל"מ | D10: 45676 | E10: 45679 | F10: 45658 | G10: 4 | H10: 4 | I10: 0 | J10: 0 | K10: 0 | L10: ='📈 היסטוריית שכר'!C9 -> 876.93 | M10: =L10*H10 -> 3507.72 | O10: 3710 | P10: 45697 | Q10: =O10-M10 -> 202.28 | S10: 45717
A11: 203661004 | B11: אריאל אליה | C11: מל"מ | D11: 45718 | E11: 45721 | F11: 45717 | G11: 4 | H11: 4 | I11: 0 | J11: 0 | K11: 0 | L11: 876.93 | M11: =L11*H11 -> 3507.72 | O11: 3739 | P11: 45985 | Q11: =O11-M11 -> 231.28 | S11: 46023
A12: 203661004 | B12: אריאל אליה | C12: מל"מ | D12: 45770 | E12: 45770 | F12: 45748 | G12: 1 | H12: 1 | I12: 0 | J12: 0 | K12: 0 | L12: 876.93 | M12: =L12*H12 -> 876.93 | O12: 691 | P12: 45985 | Q12: =O12-M12 -> -185.93 | S12: 46023
A13: 203661004 | B13: אריאל אליה | C13: מל"מ | D13: 45774 | E13: 45774 | F13: 45748 | G13: 1 | H13: 1 | I13: 0 | J13: 0 | K13: 0 | L13: 876.93 | M13: =L13*H13 -> 876.93 | O13: 691 | P13: 45985 | Q13: =O13-M13 -> -185.93 | S13: 46023
A14: 203661004 | B14: אריאל אליה | C14: מל"מ | D14: 45781 | E14: 45801 | F14: 45778 | G14: 21 | H14: 15 | I14: 3 | J14: 3 | K14: 0 | L14: 876.93 | M14: =L14*H14 -> 13153.95 | O14: 14425 | P14: 45985 | Q14: =O14-M14 -> 1271.05 | S14: 46023
A15: 203661004 | B15: אריאל אליה | C15: מל"מ | D15: 45886 | E15: 45890 | F15: 45870 | G15: 5 | H15: 5 | I15: 0 | J15: 0 | K15: 0 | L15: 876.93 | M15: =L15*H15 -> 4384.65 | O15: =288+M15 -> 4672.65 | P15: 45985 | Q15: =O15-M15 -> 288 | S15: 46023 | T15: לבדוק מדוע לא שולם
A16: 315919936 | B16: דניאל בנדרימר | C16: מל"מ | D16: 45683 | E16: 45687 | F16: 45658 | G16: 5 | H16: 5 | I16: 0 | J16: 0 | K16: 0 | L16: ='📈 היסטוריית שכר'!C11 -> 670.2815 | M16: =L16*H16 -> 3351.4075 | O16: 3981 | P16: 45697 | Q16: =O16-M16 -> 629.59252 | S16: 45717
A17: 315919936 | B17: דניאל בנדרימר | C17: מל"מ | D17: 45769 | E17: 45777 | F17: 45748 | G17: 9 | H17: 7 | I17: 1 | J17: 1 | K17: 0 | L17: 670.2815 | M17: =L17*H17 -> 4691.9705 | N17: 677 | O17: 5078 | P17: 45988 | Q17: =O17-M17+N17 -> 1063.0295 | S17: 46023
A18: 315919936 | B18: דניאל בנדרימר | C18: מל"מ | D18: 45778 | E18: 45806 | F18: 45778 | G18: 29 | H18: =G18-4*2 -> 21 | I18: 4 | J18: 4 | K18: 0 | L18: 670 | M18: =L18*H18 -> 14070 | O18: 16362 | P18: 45988 | Q18: =O18-M18+N18 -> 2292 | S18: 46023
A19: 315919936 | B19: דניאל בנדרימר | C19: מל"מ | D19: 45811 | E19: 45838 | F19: 45809 | G19: 28 | H19: 20 | I19: 4 | J19: 4 | K19: 0 | L19: 670.2815 | M19: =L19*H19 -> 13405.63 | O19: 15114 | P19: 45988 | Q19: =O19-M19+N19 -> 1708.3701 | S19: 46023
A20: 315919936 | B20: דניאל בנדרימר | C20: מל"מ | D20: 45845 | E20: 45845 | F20: 45839 | G20: 1 | H20: 1 | I20: 0 | J20: 0 | K20: 0 | L20: 670.2815 | M20: =L20*H20 -> 670.2815 | N20: 216 | O20: 540 | P20: 45988 | Q20: =O20-M20+N20 -> 85.718505 | S20: 46023
A21: 315919936 | B21: דניאל בנדרימר | C21: מל"מ | D21: 45865 | E21: 45866 | F21: 45839 | G21: 2 | H21: 2 | I21: 0 | J21: 0 | K21: 0 | L21: 670.2815 | M21: =L21*H21 -> 1340.563 | N21: 432 | O21: 1080 | P21: 45988 | Q21: =O21-M21+N21 -> 171.43701 | S21: 46023
A22: 315919936 | B22: דניאל בנדרימר | C22: מל"מ | D22: 45875 | E22: 45876 | F22: 45870 | G22: 2 | H22: 2 | I22: 0 | J22: 0 | K22: 0 | L22: 670.2815 | M22: =L22*H22 -> 1340.563 | O22: 1511 | P22: 46054 | Q22: =O22-M22 -> 170.43701 | S22: 46023
A23: 315919936 | B23: דניאל בנדרימר | C23: מל"מ | D23: 45909 | E23: 45911 | F23: 45901 | G23: 3 | H23: 3 | I23: 0 | J23: 0 | K23: 0 | L23: 670.2815 | M23: =L23*H23 -> 2010.8445 | O23: 2267 | P23: 46054 | Q23: =O23-M23 -> 256.15551 | S23: 46023
A24: 315919936 | B24: דניאל בנדרימר | C24: מל"מ | D24: 45930 | E24: 45930 | F24: 45901 | G24: 1 | H24: 1 | I24: 0 | J24: 0 | K24: 0 | L24: 670.2815 | M24: =L24*H24 -> 670.2815 | O24: 540 | P24: 46054 | Q24: =O24-M24 -> -130.2815 | S24: 46023
A25: חיים ראש | B25: חיים ראש | C25: מל"מ | D25: 45813 | E25: 45813 | F25: 45809 | G25: 1 | H25: 1 | I25: 0 | J25: 0 | K25: 0 | L25: ='📈 היסטוריית שכר'!C12 -> 1084.4024 | M25: =L25*H25 -> 1084.4024 | O25: 1497 | P25: 45988 | Q25: =O25-M25 -> 412.5976 | S25: 46023
A26: 25474677 | B26: יום טוב מוסארי | C26: רוה"מ | D26: 45708 | E26: 45708 | F26: 45689 | G26: 1 | H26: 1 | I26: 0 | J26: 0 | K26: 0 | L26: ='📈 היסטוריית שכר'!C13 -> 1180.1108 | M26: =L26*H26 -> 1180.1108 | O26: 1598 | P26: 46054 | Q26: =O26-M26 -> 417.88925 | T26: לא שולם- שיומי יבדוק סכומי תשלום קוד
A27: 25474677 | B27: יום טוב מוסארי | C27: רוה"מ | D27: 45711 | E27: 45711 | F27: 45689 | G27: 1 | H27: 1 | I27: 0 | J27: 0 | K27: 0 | L27: 1180.1108 | M27: =L27*H27 -> 1180.1108 | O27: 1598 | P27: 46054 | Q27: =O27-M27 -> 417.88925 | T27: לא שולם- שיומי יבדוק סכומי תשלום קוד
A28: 25474677 | B28: יום טוב מוסארי | C28: רוה"מ | D28: 45820 | E28: 45837 | F28: 45809 | G28: 18 | H28: 12 | I28: 3 | J28: 3 | K28: 0 | L28: 1180.1108 | M28: =L28*H28 -> 14161.329 | N28: 630 | O28: =5458+1624 -> 7082 | P28: 45988 | Q28: =O28-M28+N28 -> -6449.329 | T28: לא שולם- שיומי יבדוק סכומי תשלום קוד
A29: 22201347 | B29: יורם שלמה | C29: רוה"מ | D29: 45658 | E29: 45658 | F29: 45658 | G29: 1 | H29: 1 | I29: 0 | J29: 0 | K29: 0 | L29: ='📈 היסטוריית שכר'!C15 -> 1107.3373 | M29: =L29*H29 -> 1107.3373 | O29: 1051 | P29: 45697 | Q29: =O29-M29 -> -56.337333 | S29: 45809
A30: 22201347 | B30: יורם שלמה | C30: רוה"מ | D30: 45658 | E30: 45658 | F30: 45658 | G30: 1 | H30: 0 | I30: 0 | J30: 0 | K30: 0 | L30: 1107.3373 | M30: =L30*H30 -> 0 | N30: 420 | P30: 45775 | Q30: =N30-M30 -> 420 | S30: 45809
A31: 22201347 | B31: יורם שלמה | C31: רוה"מ | D31: 45676 | E31: 45680 | F31: 45658 | G31: 5 | H31: 5 | I31: 0 | J31: 0 | K31: 0 | L31: 1107.3373 | M31: =L31*H31 -> 5536.6867 | O31: 5257 | P31: 45697 | Q31: =O31-M31 -> -279.68666 | S31: 45809
A32: 22201347 | B32: יורם שלמה | C32: רוה"מ | D32: 45676 | E32: 45680 | F32: 45658 | G32: 5 | H32: 0 | I32: 0 | J32: 1 | K32: 0 | L32: 1107.3373 | M32: =L32*H32 -> 0 | N32: 2103 | P32: 45775 | Q32: =N32-M32 -> 2103 | R32: -3352 | S32: 45809
A33: 22201347 | B33: יורם שלמה | C33: רוה"מ | D33: 45698 | E33: 45698 | F33: 45689 | G33: 1 | H33: 1 | I33: 0 | J33: 0 | K33: 0 | L33: 1107.3373 | M33: =L33*H33 -> 1107.3373 | O33: 1174 | P33: 45770 | Q33: =O33-M33 -> 66.662667
A34: 22201347 | B34: יורם שלמה | C34: רוה"מ | D34: 45698 | E34: 45698 | F34: 45689 | G34: 1 | H34: 0 | I34: 0 | J34: 0 | K34: 0 | L34: 1107.3373 | M34: =L34*H34 -> 0 | N34: 666 | P34: 45800 | Q34: =N34-M34 -> 666
A35: 22201347 | B35: יורם שלמה | C35: רוה"מ | D35: 45706 | E35: 45707 | F35: 45689 | G35: 2 | H35: 2 | I35: 0 | J35: 0 | K35: 0 | L35: 1107.3373 | M35: =L35*H35 -> 2214.6747 | O35: 3287 | P35: 45770 | Q35: =O35-M35 -> 1072.3253
A36: 22201347 | B36: יורם שלמה | C36: רוה"מ | D36: 45714 | E36: 45714 | F36: 45689 | G36: 1 | H36: 1 | I36: 0 | J36: 0 | K36: 0 | L36: 1107.3373 | M36: =L36*H36 -> 1107.3373 | O36: 1174 | P36: 45770 | Q36: =O36-M36 -> 66.662667
A37: 22201347 | B37: יורם שלמה | C37: רוה"מ | D37: 45714 | E37: 45714 | F37: 45689 | G37: 1 | H37: 0 | I37: 0 | J37: 0 | K37: 0 | L37: 1107.3373 | M37: =L37*H37 -> 0 | N37: 666 | P37: 45800 | Q37: =N37-M37 -> 666
A38: 22201347 | B38: יורם שלמה | C38: רוה"מ | D38: 45720 | E38: 45720 | F38: 45717 | G38: 1 | H38: 1 | I38: 0 | J38: 0 | K38: 0 | L38: 1107.3373 | M38: =L38*H38 -> 1107.3373 | O38: 1233 | P38: 45770 | Q38: =O38-M38 -> 125.66267
A39: 22201347 | B39: יורם שלמה | C39: רוה"מ | D39: 45720 | E39: 45720 | F39: 45717 | G39: 1 | H39: 0 | I39: 0 | J39: 0 | K39: 0 | L39: 1107.3373 | M39: =L39*H39 -> 0 | N39: 666 | P39: 45834 | Q39: =N39-M39 -> 666
A40: 22201347 | B40: יורם שלמה | C40: רוה"מ | D40: 45733 | E40: 45734 | F40: 45717 | G40: 2 | H40: 2 | I40: 0 | J40: 0 | K40: 0 | L40: 1107.3373 | M40: =L40*H40 -> 2214.6747 | O40: =1233+2466 -> 3699 | P40: 45770 | Q40: =O40-M40 -> 1484.3253
...

Sheet מילואים 2025- מקאנו
A1: תאריך | B1: שם עובד | C1: מחלקה | D1: מילואים | E1: הגשה
A2: 45956 | B2: אבישי שרון מהדקאר | C2: תומר | D2: 1
A3: 45957 | B3: אבישי שרון מהדקאר | C3: תומר | D3: 1
A4: 45958 | B4: אבישי שרון מהדקאר | C4: תומר | D4: 1
A5: 45959 | B5: אבישי שרון מהדקאר | C5: תומר | D5: 1
A6: 45977 | B6: אבישי שרון מהדקאר | C6: תומר | D6: 1
A7: 45978 | B7: אבישי שרון מהדקאר | C7: תומר | D7: 1
A8: 45979 | B8: אבישי שרון מהדקאר | C8: תומר | D8: 1
A9: 45735 | B9: אוראל שווקי | C9: רפאל | D9: 1
A10: 46005 | B10: אוראל שווקי | C10: רפאל | D10: 1 | E10: 08.01.2026
A11: 46006 | B11: אוראל שווקי | C11: רפאל | D11: 1 | E11: 08.01.2026
A12: 45901 | B12: אורי אשתר | C12: מל"מ | D12: 1
A13: 45902 | B13: אורי אשתר | C13: מל"מ | D13: 1
A14: 45903 | B14: אורי אשתר | C14: מל"מ | D14: 1
A15: 45904 | B15: אורי אשתר | C15: מל"מ | D15: 1
A16: 45905 | B16: אורי אשתר | C16: מל"מ | D16: 1
A17: 45906 | B17: אורי אשתר | C17: מל"מ | D17: 1
A18: 45907 | B18: אורי אשתר | C18: מל"מ | D18: 1
A19: 45908 | B19: אורי אשתר | C19: מל"מ | D19: 1
A20: 45909 | B20: אורי אשתר | C20: מל"מ | D20: 1
A21: 45910 | B21: אורי אשתר | C21: מל"מ | D21: 1
A22: 45911 | B22: אורי אשתר | C22: מל"מ | D22: 1
A23: 45912 | B23: אורי אשתר | C23: מל"מ | D23: 1
... A33: 45973 | B33: אורי דוד עברי | C33: מל"מ | D33: 1
A34: 45998 | B34: אורי דוד עברי | C34: מל"מ | D34: 1 | E34: 08.01.2026
A35: 45999 | B35: אורי דוד עברי | C35: מל"מ | D35: 1 | E35: 08.01.2026
A36: 46009 | B36: אורי דוד עברי | C36: מל"מ | D36: 1 | E36: 08.01.2026
A37: 46014 | B37: אורי דוד עברי | C37: מל"מ | D37: 1 | E37: 08.01.2026
A38: 46019 | B38: אורי דוד עברי | C38: מל"מ | D38: 1 | E38: 08.01.2026
A39: 45658 | B39: אייל מלח | C39: רפאל | D39: 1
A40: 45659 | B40: אייל מלח | C40: רפאל | D40: 1
A41: 45660 | B41: אייל מלח | C41: רפאל | D41: 1
A42: 45796 | B42: אייל מלח | C42: רפאל | D42: 1
A43: 45797 | B43: אייל מלח | C43: רפאל | D43: 1
A44: 45798 | B44: אייל מלח | C44: רפאל | D44: 1
A45: 45820 | B45: אייל מלח | C45: רפאל | D45: 1
A46: 45821 | B46: אייל מלח | C46: רפאל | D46: 1
A47: 45822 | B47: אייל מלח | C47: רפאל | D47: 1
A48: 45823 | B48: אייל מלח | C48: רפאל | D48: 1
A49: 45824 | B49: אייל מלח | C49: רפאל | D49: 1
...
